Workbook

Sheet TABLA RESUMEN
A6: Cuenta de Tipo Dispositivo | B6: Etiquetas de columna
A7: Etiquetas de fila | B7: AIO | C7: DESKTOP | D7: DOCKING | E7: MONITOR | F7: NOTEBOOK | G7: Total general
A8: ANTOFAGASTA | B8: 8 | C8: 16 | D8: 6 | E8: 75 | F8: 41 | G8: 146
A9: ARICA | E9: 2 | G9: 2
A10: CABILDO | C10: 1 | E10: 1 | G10: 2
A11: CALAMA | B11: 3 | C11: 9 | D11: 1 | E11: 10 | F11: 7 | G11: 30 | J11: Q INVENTARIO
A12: CONCEPCIÓN | B12: 8 | C12: 21 | D12: 8 | E12: 81 | F12: 66 | G12: 184
A13: COQUIMBO | B13: 38 | C13: 32 | D13: 22 | E13: 150 | F13: 106 | G13: 348 | J13: =GETPIVOTDATA("Tipo Dispositivo",$A$6) -> 3086
A14: LA LIGUA | B14: 2 | C14: 2 | D14: 3 | E14: 11 | F14: 14 | G14: 32
A15: LAS CABRAS | C15: 1 | E15: 1 | G15: 2
A16: MEJILLONES | C16: 2 | E16: 3 | F16: 1 | G16: 6
A17: OVALLE | B17: 2 | C17: 3 | D17: 2 | E17: 8 | F17: 10 | G17: 25 | J17: OBJETIVO
A18: PICHILEMU | B18: 1 | C18: 1 | E18: 8 | F18: 3 | G18: 13
A19: RANCAGUA | B19: 8 | C19: 28 | D19: 9 | E19: 83 | F19: 52 | G19: 180 | J19: 3500
A20: RENGO | B20: 1 | C20: 3 | E20: 3 | G20: 7
A21: SAN VICENTE DE TAGUA TAGUA | B21: 2 | C21: 1 | E21: 11 | F21: 8 | G21: 22
A22: SANTIAGO | B22: 15 | C22: 42 | D22: 26 | E22: 432 | F22: 446 | G22: 961
A23: TALTAL | C23: 2 | E23: 4 | F23: 2 | G23: 8 | J23: AVANCE
A24: TEMUCO | B24: 13 | C24: 14 | D24: 3 | E24: 55 | F24: 41 | G24: 126
A25: TOCOPILLA | C25: 5 | D25: 1 | E25: 11 | F25: 2 | G25: 19 | J25: =GETPIVOTDATA("Tipo Dispositivo",$A$6)/J19 -> 0.88171429
A26: VICUÑA | B26: 1 | C26: 2 | D26: 3 | E26: 4 | F26: 4 | G26: 14
A27: VIÑA DEL MAR | B27: 2 | C27: 6 | D27: 11 | E27: 23 | F27: 20 | G27: 62
A28: MAULE | E28: 1 | G28: 1
A29: TALCA | B29: 2 | C29: 29 | D29: 17 | E29: 97 | F29: 40 | G29: 185
A30: PUCON | B30: 2 | C30: 1 | E30: 7 | F30: 5 | G30: 15 | J30: Usuarios
A31: CHILLÁN | B31: 1 | C31: 6 | E31: 20 | F31: 14 | G31: 41
A32: LA SERENA | C32: 6 | E32: 5 | G32: 11 | J32: =GETPIVOTDATA("Tipo Dispositivo",$A$6,"Tipo Dispositivo","AIO")+GETPIVOTDATA("Tipo Dispositivo",$A$6,"Tipo Dispositivo","DESKTOP")+GETPIVOTDATA("Tipo Dispositivo",$A$6,"Tipo Dispositivo","NOTEBOOK") -> 1607
A33: TALCAHUANO | B33: 1 | C33: 3 | E33: 3 | G33: 7
A34: SAN FERNANDO | B34: 1 | C34: 4 | E34: 16 | F34: 10 | G34: 31
A35: VILLARRICA | C35: 9 | D35: 2 | E35: 17 | F35: 11 | G35: 39
A36: SAN PEDRO DE LA PAZ | E36: 3 | F36: 6 | G36: 9
A37: LINARES | C37: 5 | D37: 1 | E37: 9 | F37: 10 | G37: 25
A38: COELEMU | C38: 1 | G38: 1
A39: CURACAVI | B39: 3 | E39: 3 | F39: 3 | G39: 9
A40: CORONEL | C40: 3 | E40: 3 | G40: 6
A41: PUENTE ALTO | C41: 8 | F41: 3 | G41: 11
A42: QUIRIHUE | C42: 2 | E42: 9 | F42: 7 | G42: 18
A43: LOS ÁNGELES | C43: 6 | E43: 12 | F43: 6 | G43: 24
A44: COPIAPO | B44: 5 | E44: 6 | F44: 5 | G44: 16
A45: IQUIQUE | B45: 6 | C45: 10 | E45: 38 | F45: 38 | G45: 92
...

Sheet Hoja1
A1: Dirección | B1: AVENIDA PRESIDENTE RIESCO N° 5561
A3: Etiquetas de fila | B3: qqq
A4: LUIS SEBASTIAN | B4: =VLOOKUP(A4,[1]Hoja8!$A$1:$F$465,2,FALSE) -> CGE S.A
A5: ADAM PATRICIO CASTILLO SALAS | B5: =VLOOKUP(A5,[1]Hoja8!$A$1:$F$465,2,FALSE) -> CGE Servicios S.A.
A6: ADELIS VIRGINIA MENDEZ VARGAS | B6: =VLOOKUP(A6,[1]Hoja8!$A$1:$F$465,2,FALSE) -> CGE Servicios S.A.
A7: ADOLFO ENRIQUE ALVARADO JELDRES | B7: =VLOOKUP(A7,[1]Hoja8!$A$1:$F$465,2,FALSE) -> CGE Servicios S.A.
A8: ALEJANDRA ANDREA SOLA STEVENSON | B8: =VLOOKUP(A8,[1]Hoja8!$A$1:$F$465,2,FALSE) -> CGE Servicios S.A.
A9: ALEJANDRA ROSARIO APARICIO SEPULVEDA | B9: =VLOOKUP(A9,[1]Hoja8!$A$1:$F$465,2,FALSE) -> CGE Servicios S.A.
A10: ALVARO MALDONADO | B10: =VLOOKUP(A10,[1]Hoja8!$A$1:$F$465,2,FALSE) -> #N/A
A11: ANA CECILIA PACHECO GARRIDO | B11: =VLOOKUP(A11,[1]Hoja8!$A$1:$F$465,2,FALSE) -> CGE Servicios S.A.
A12: ANA MARIA ARIAS ATHANACIU | B12: =VLOOKUP(A12,[1]Hoja8!$A$1:$F$465,2,FALSE) -> CGE Servicios S.A.
A13: ANA MARIA RODRIGUEZ ORELLANA | B13: =VLOOKUP(A13,[1]Hoja8!$A$1:$F$465,2,FALSE) -> CGE Servicios S.A.
A14: ANDREA MARISOL BELTRAN FUENTES | B14: =VLOOKUP(A14,[1]Hoja8!$A$1:$F$465,2,FALSE) -> CGE Servicios S.A.
A15: ANDREA PAZ VIACAVA NAZAR | B15: =VLOOKUP(A15,[1]Hoja8!$A$1:$F$465,2,FALSE) -> CGE Servicios S.A.
... A475: Total general | B475: =VLOOKUP(A475,[1]Hoja8!$A$1:$F$465,2,FALSE) -> #N/A
B476: =VLOOKUP(A476,[1]Hoja8!$A$1:$F$465,2,FALSE) -> #N/A
B477: =VLOOKUP(A477,[1]Hoja8!$A$1:$F$465,2,FALSE) -> #N/A
B478: =VLOOKUP(A478,[1]Hoja8!$A$1:$F$465,2,FALSE) -> #N/A
B479: =VLOOKUP(A479,[1]Hoja8!$A$1:$F$465,2,FALSE) -> #N/A
B480: =VLOOKUP(A480,[1]Hoja8!$A$1:$F$465,2,FALSE) -> #N/A
B481: =VLOOKUP(A481,[1]Hoja8!$A$1:$F$465,2,FALSE) -> #N/A
B482: =VLOOKUP(A482,[1]Hoja8!$A$1:$F$465,2,FALSE) -> #N/A

Sheet CONSOLIDADO
A1: Activo Fijo | B1: Rotulo Entel | C1: Tipo Dispositivo | D1: Unidades | E1: Teléfono | F1: Nombre de Usuario | G1: Usuario de RED | H1: Número de Serie | I1: Hostname | J1: Marca | K1: Modelo | L1: Dirección | M1: Piso | N1: Comuna | O1: Región | P1: Ciudad | Q1: Area | R1: Necesita Alzador | S1: Nombre de usuario Responsable | T1: Tipo Usuario | U1: Observaciones | V1: Observaciones 2 | W1: D | X1: FOTOS
A2: No visible | B2: CGE005656 | C2: NOTEBOOK | D2: 1 | E2: NO | F2: ALEX MAURICIO CEBALLOS DURAN | G2: AMCEBALLOSD | H2: HLZB9W3 | I2: HLZB9W3 | J2: DELL | K2: DELL LATITUDE 7440 | L2: 2 NORTE 798 | M2: 2 | N2: TALCA | O2: MAULE | P2: TALCA | Q2: ATENCIÓN COMERCIAL | R2: NO | S2: Funciona correctamente | T2: INTERNO | X2: https://drive.google.com/open?id=1UYjhZ49z3HhuQyQqfJCrImSWTRT9fn6t
A3: 210000063856-0000 | B3: CGE005487 | C3: MONITOR | D3: 1 | E3: SI | F3: ALEX MAURICIO CEBALLOS DURAN | G3: AMCEBALLOSD | H3: CN 0101CF | I3: NO APLICA | J3: DELL | K3: NO VISIBLE | L3: 2 NORTE 798 | M3: 2 | N3: TALCA | O3: MAULE | P3: TALCA | Q3: ATENCIÓN COMERCIAL | R3: N/A | S3: Funciona correctamente | T3: INTERNO | X3: https://drive.google.com/open?id=1ksr3n7NG98C1Ah1n21iDFfRPlIclUPhl
A4: 210000028136-0000 | B4: CGE007351 | C4: DESKTOP | D4: 1 | E4: NO | F4: CAROL SANDOVAL | G4: CSANDOVAL | H4: MXL1240NZ4 | I4: DTMXL1240NZ4 | J4: HP | K4: 8200 | L4: 2 NORTE 798 | M4: 1 | N4: TALCA | O4: MAULE | P4: TALCA | Q4: ATENCIÓN COMERCIAL | R4: NO | S4: Funciona correctamente | T4: INTERNO | W4: https://drive.google.com/open?id=1Eve0NnLSgy9mqSRjGNcuRfdhoIWIKbg5
A5: 210000022369-0000 | B5: CGE007441 | C5: MONITOR | D5: 1 | E5: SI | F5: CATHERINE ALIAGA | G5: NO APLICA | H5: CN ON445N 74261 09R 2KGS | I5: NO APLICA | J5: DELL | K5: E170SC | L5: 2 NORTE 798 | M5: 2 | N5: TALCA | O5: MAULE | P5: TALCA | Q5: ATENCIÓN COMERCIAL | R5: N/A | S5: Funciona correctamente | T5: INTERNO | W5: https://drive.google.com/open?id=1XfxRjNea402XQg9I41DeRy_PM2GozToe
A6: 210000064187-0000 | B6: CGE006673 | C6: MONITOR | D6: 1 | E6: SI | F6: CESAR PEREZ | G6: NO APLICA | H6: VN 0MDK14 WS700 418 A3BU A02 | I6: NO APLICA | J6: DELL | K6: P2722HE | L6: 2 NORTE 798 | M6: 2 | N6: TALCA | O6: MAULE | P6: TALCA | Q6: ATENCIÓN COMERCIAL | R6: N/A | S6: Funciona correctamente | T6: INTERNO | W6: https://drive.google.com/open?id=16Fff9yD8Zi6ABRYWY3ghIIvFaYfEOqlL
A7: 210000061160-0000 | B7: CGE001478 | C7: NOTEBOOK | D7: 1 | E7: NO | F7: CHRISTIAN VALENZUELA | G7: CVALENZUELAM | H7: 5CD207HCW1 | I7: NB5CD207HCW1 | J7: HP | K7: HP PROBOOK 440 G8 | L7: 2 NORTE 798 | M7: 2 | N7: TALCA | O7: MAULE | P7: TALCA | Q7: ATENCIÓN COMERCIAL | R7: NO | S7: Funciona correctamente | T7: INTERNO | W7: https://drive.google.com/open?id=1Ci_vMFBzTmpHRth_VYaolzm3mA-ACqHf
A8: No visible | B8: NO VISIBLE | C8: MONITOR | D8: 1 | E8: SI | F8: CHRISTIAN VALENZUELA | G8: NO APLICA | H8: CNN7322821 | I8: NO APLICA | J8: HP | K8: NO VISIBLE | L8: 2 NORTE 798 | M8: 2 | N8: TALCA | O8: MAULE | P8: TALCA | Q8: ATENCIÓN COMERCIAL | R8: N/A | S8: Funciona correctamente | T8: INTERNO
A9: 210000028014-0000 | B9: NO POSEE | C9: DESKTOP | D9: 1 | E9: NO | F9: DANIEL BECERRA | G9: EJECUTIVODEDM | H9: MXL1341PFN | I9: DTMXL1341PFN | J9: HP | K9: 8200 | L9: 2 NORTE 798 | M9: 1 | N9: TALCA | O9: MAULE | P9: TALCA | Q9: ATENCIÓN COMERCIAL | R9: NO | S9: Funciona correctamente | T9: INTERNO | W9: https://drive.google.com/open?id=18KT5RhA1EtSc1jadWFCXf3yy_iMA4MQN
A10: 210000064143-0000 | B10: CGE006019 | C10: NOTEBOOK | D10: 1 | E10: NO | F10: DANIELA MUÑOZ | G10: DGMUNOZG | H10: 7ZQRK24 | I10: NB7ZQRK24 | J10: DELL | K10: LATITUDE 5440 | L10: 2 NORTE 798 | M10: 2 | N10: TALCA | O10: MAULE | P10: TALCA | Q10: ATENCIÓN COMERCIAL | R10: NO | S10: Funciona correctamente, sin daños | T10: INTERNO | W10: https://drive.google.com/open?id=1azvWQEUyAAdyBM7rNfcxqo6vgShvnEBY
A11: 210000060388-0000 | B11: NO PRESENTA | C11: MONITOR | D11: 1 | E11: SI | F11: DANIELA MUÑOZ | G11: NO APLICA | H11: 1CR1202Z0 | I11: NO APLICA | J11: HP | K11: P24V G4 FHD | L11: 2 NORTE 798 | M11: 2 | N11: TALCA | O11: MAULE | P11: TALCA | Q11: ATENCIÓN COMERCIAL | S11: Funciona correctamente, sin daños | T11: INTERNO | W11: https://drive.google.com/open?id=1Mfo5XnJauk3fszNzpXXIeAV2R0X-g_9p
A12: 210000066404-0000 | B12: CGE010618 | C12: DESKTOP | D12: 1 | E12: NO | F12: DENISSE ANDREA CANCINO VASQUEZ | G12: DACANCINOV | H12: NO VISIBLE | I12: USUARIO NO SE ENCUENTRA EN LA SUCURSAL | J12: LENOVO | K12: THINKCENTRE | L12: 2 NORTE 798 | M12: 1 | N12: TALCA | O12: MAULE | P12: TALCA | Q12: ATENCIÓN COMERCIAL | R12: NO | T12: INTERNO | W12: https://drive.google.com/open?id=1BUzVzPq2soWMZiz0RahELD6IpBmdsbGo
A13: 210000061076-0000 | B13: CGE001486 | C13: NOTEBOOK | D13: 1 | E13: NO | F13: FABIAN RODRIGUEZ | G13: FRODRIGUEZ | H13: 5CD207HCG5 | I13: NB5CD207HCG5 | J13: HP | K13: HP PROBOOK 440 G8 | L13: 2 NORTE 798 | M13: 2 | N13: TALCA | O13: MAULE | P13: TALCA | Q13: ATENCIÓN COMERCIAL | R13: NO | S13: Funciona correctamente | T13: INTERNO | W13: https://drive.google.com/open?id=1gkznBaGTF2dLimo0rW8cp9lRSavggHGo
A14: 210000027309-0000 | B14: CGE003118 | C14: MONITOR | D14: 1 | E14: SI | F14: FABIAN RODRIGUEZ | G14: NO APLICA | H14: CNC117PWXH | I14: NO APLICA | J14: HP | K14: COMPAC LE1711 | L14: 2 NORTE 798 | M14: 2 | N14: TALCA | O14: MAULE | P14: TALCA | Q14: ATENCIÓN COMERCIAL | R14: N/A | S14: Funciona correctamente | T14: INTERNO | W14: https://drive.google.com/open?id=1K-92ZoXyhiEL8cJS9ImOcOGstQXMdc19
A15: 210000063805-0000 | B15: CGE005481 | C15: MONITOR | D15: 1 | E15: SI | F15: FRANCISCA CASANOVA | G15: FCASANOVA | H15: CN-0101CF | I15: NO APLICA | J15: DELL | K15: DELL 24 | L15: 2 NORTE 798 | M15: 2 | N15: TALCA | O15: MAULE | P15: TALCA | R15: N/A | S15: Funciona correctamente | T15: INTERNO | X15: https://drive.google.com/open?id=1OWLjQIc9hFuJw34P1F0AeeZZLsyDPjBW
A16: 210000049155-0000 | B16: NO PRESENTA | C16: NOTEBOOK | D16: 1 | E16: NO | F16: FRANCISCA CASANOVA | G16: FCASANOVA | H16: NB-5CG7411CGS | I16: NB-5CG7411CGS | J16: HP | K16: HO ELITEBOOK | L16: 2 NORTE 798 | M16: 2 | N16: TALCA | O16: MAULE | P16: TALCA | Q16: ATENCIÓN COMERCIAL | R16: NO | S16: Funciona correctamente, sin daños | T16: INTERNO | W16: https://drive.google.com/open?id=13MrZyLTtBgOQOSfaP22MTOMjCpHu57iM
A17: 210000042619-0000 | B17: NO VISIBLE | C17: DOCKING | D17: 1 | E17: NO | F17: FRANCISCA CASANOVA | G17: NO APLICA | H17: 5CG532W7M2 | I17: NO APLICA | J17: HP | K17: 2013 ULTRASLIM DOCKINGSTATION | L17: 2 NORTE 798 | M17: 2 | N17: TALCA | O17: MAULE | P17: TALCA | Q17: ATENCIÓN COMERCIAL | R17: N/A | S17: Funciona correctamente | T17: INTERNO | W17: https://drive.google.com/open?id=1KgdVXe50NPjhenUAwPZB2l8MQhpt3zJ3
A18: 210000021877-0000 | B18: CGE007341 | C18: DESKTOP | D18: 1 | E18: NO | F18: ISABEL ALEJANDRA GARAUD CARRASCO | G18: IAGARAUDC | H18: MXL1341PF0 | I18: DTMXL1341PF0 | J18: HP | K18: HPCOMPAQ 8200 ELITE SMALLFORM FACTOR | L18: 2 NORTE 798 | M18: 1 | N18: TALCA | O18: MAULE | P18: TALCA | Q18: ATENCIÓN COMERCIAL | R18: N/A | S18: Funciona correctamente | T18: INTERNO | W18: https://drive.google.com/open?id=1wDdVFioG9-W2i72U5fOTxSYcqZRhfMaA
A19: 210000026553-0000 | B19: CGE007338 | C19: MONITOR | D19: 1 | E19: SI | F19: ISABEL ALEJANDRA GARAUD CARRASCO | G19: N/A | H19: CNC115PRSF | I19: N/A | J19: HP | K19: COMPAQ LE1711 | L19: 2 NORTE 798 | M19: 1 | N19: TALCA | O19: MAULE | P19: TALCA | Q19: ATENCIÓN COMERCIAL | R19: N/A | T19: INTERNO | W19: https://drive.google.com/open?id=1UFsSYBUkc3ROuJjqM3lcpY27xcH5ICCS
A20: 210000027733-0000 | B20: CGE007348 | C20: DESKTOP | D20: 1 | E20: NO | F20: LAURA ANDREA HERRERA ESPINOZA | G20: LAHERRERAE | H20: MXL13611JH | I20: DTMXL13611JH | J20: HP | K20: NO VISIBLE | L20: 2 NORTE 798 | M20: 1 | N20: TALCA | O20: MAULE | P20: TALCA | Q20: ATENCIÓN COMERCIAL | R20: NO | S20: Funciona correctamente | T20: INTERNO | W20: https://drive.google.com/open?id=1aRrj-kv46hiwfTzHuok2Wl0QmrhOiTBc
A21: 210000027224-0000 | B21: CGE007347 | C21: MONITOR | D21: 1 | E21: SI | F21: LAURA ANDREA HERRERA ESPINOZA | G21: N/A | H21: CNC118QSK6 | I21: N/A | J21: HP | K21: COMPAQ LE1711 | L21: 2 NORTE 798 | M21: 1 | N21: TALCA | O21: MAULE | P21: TALCA | Q21: ATENCIÓN COMERCIAL | R21: N/A | T21: INTERNO | W21: https://drive.google.com/open?id=1XRPnJhBah4l1YyNhYj2TUR7HTS8QmV5u
A22: 210000002744-0000 | B22: CGE007353 | C22: MONITOR | D22: 1 | E22: SI | F22: LAURA ANDREA HERRERA ESPINOZA | G22: N/A | H22: CNC118QRQ8 | I22: N/A | J22: HP | K22: COMPAQ LE1711 | L22: 2 NORTE 798 | M22: 1 | N22: TALCA | O22: MAULE | P22: TALCA | Q22: ATENCIÓN COMERCIAL | R22: N/A | T22: INTERNO | W22: https://drive.google.com/open?id=1TPfG2U-1zrIaIqDrGFAwYMyH-jZsJD_4
A23: 210000066506-0000 | B23: CGE010550 | C23: DESKTOP | D23: 1 | E23: NO | F23: LUISA GALVEZ | G23: LIGALVEZT | H23: NO VISIBLE | I23: PERSONA DEL EQUIPO AUSENTE | K23: TINKCENTRE | L23: 2 NORTE 798 | M23: 1 | N23: TALCA | O23: MAULE | P23: TALCA | Q23: ATENCIÓN COMERCIAL | R23: N/A | S23: Funciona correctamente | T23: INTERNO | W23: https://drive.google.com/open?id=1Yi2VoyEI3azCrG33o4KMfwbwmcOewNlN
A24: 210000062155-0000 | B24: CGE000091 | C24: DESKTOP | D24: 1 | E24: NO | F24: LUISA GALVEZ | G24: LIGALVEZT | H24: 4CE238B2BB | I24: DT4CE238B2BB | J24: HP | K24: HP PRO SFF 400 G9 | L24: 2 NORTE 798 | M24: 1 | N24: TALCA | O24: MAULE | P24: TALCA | Q24: ATENCIÓN COMERCIAL | R24: N/A | S24: Funciona correctamente | T24: INTERNO | W24: https://drive.google.com/open?id=1E0ir60yQrPmPz--4lwOGXA-GYlyDtBCa
A25: 210000013561-0000 | B25: CGE001393 | C25: MONITOR | D25: 1 | E25: SI | F25: LUISA IVONNE GALVEZ TAPIA | G25: N/A | H25: CN-0U072N-64180-99S-120S | I25: N/A | J25: DELL | K25: E170SC | L25: 2 NORTE 798 | M25: 1 | N25: TALCA | O25: MAULE | P25: TALCA | Q25: ATENCIÓN COMERCIAL | R25: N/A | T25: INTERNO | W25: https://drive.google.com/open?id=1Oi0SIcB8GzymuRh2pP7_D9TINNwu5saH
A26: 510000006872-0000 | B26: NO TIENE | C26: TELEFONO IP | D26: 1 | E26: NO | F26: LUISA IVONNE GALVEZ TAPIA | G26: N/A | H26: FCH12479FTL | I26: N/A | J26: CISCO | K26: CP 7911G | L26: 2 NORTE 798 | M26: 1 | N26: TALCA | O26: MAULE | P26: TALCA | Q26: ATENCIÓN COMERCIAL | R26: N/A | T26: INTERNO | W26: https://drive.google.com/open?id=1-sXUB6CVZL8-eEs2uGPXD4WWytPMUgG1
A27: 510000006867-0000 | B27: NO TIENE | C27: TELEFONO IP | D27: 1 | E27: NO | F27: LUISA IVONNE GALVEZ TAPIA | G27: N/A | H27: FCH12479H8Z | I27: N/A | J27: CISCO | K27: CP7911G | L27: 2 NORTE 798 | M27: 1 | N27: TALCA | O27: MAULE | P27: TALCA | Q27: ATENCIÓN COMERCIAL | R27: N/A | T27: INTERNO | W27: https://drive.google.com/open?id=1ONJmC46SgBN3Jtxkjy6Xpm_wmeIki6V5
A28: 210000045769-0000 | B28: CGE002684 | C28: NOTEBOOK | D28: 1 | E28: NO | F28: LUSGARDA VERGARA | G28: LVERGARA | H28: 5CG8402GOQ | I28: NB5CG8402GOQ | J28: HP | K28: ELITEBOOK 840 | L28: 2 NORTE 798 | M28: 2 | N28: TALCA | O28: MAULE | P28: TALCA | Q28: ATENCIÓN COMERCIAL | R28: SI | S28: Funciona correctamente | T28: INTERNO | W28: https://drive.google.com/open?id=1cwbcfjBnayskgSQb2laNOkFOTsOtOHFN
A29: 210000060423-0000 | B29: NO PRESENTA | C29: MONITOR | D29: 1 | E29: SI | F29: LUSGARDA VERGARA | G29: LVERGARA | H29: 1CR12102ZT | I29: NO APLICA | J29: HP | K29: P24V G4 FHD | L29: 2 NORTE 798 | M29: 2 | N29: TALCA | O29: MAULE | P29: TALCA | Q29: ATENCIÓN COMERCIAL | S29: Funciona correctamente | T29: INTERNO | W29: https://drive.google.com/open?id=1sMoJe4mq_b6D9ymj6ucrktXXqUqP6cvE
A30: NO TIENE | B30: NO TIENE | C30: NOTEBOOK | D30: 1 | E30: NO | F30: MARCIA VARAS VENEGAS | G30: N/A | H30: 5CD4484GRS | I30: N/A | J30: HP | K30: PROBOOK450 G10 | L30: 2 NORTE 798 | M30: 1 | N30: TALCA | O30: MAULE | P30: TALCA | Q30: ATENCIÓN COMERCIAL | R30: NO | S30: equipo de apoyo terreno | T30: INTERNO
A31: NO TIENE | B31: NO TIENE | C31: NOTEBOOK | D31: 1 | E31: NO | F31: MARCIA VARAS VENEGAS | G31: NO APLICA | H31: 5CD5033GL2 | I31: NO APLICA | J31: HP | K31: HP PROBOOK 450 G10 | L31: 2 NORTE 798 | M31: 1 | N31: TALCA | O31: MAULE | P31: TALCA | Q31: ATENCIÓN COMERCIAL | R31: NO | S31: Equipo apoyo terreno | T31: INTERNO | W31: https://drive.google.com/open?id=1M-np0U-PI9K62-EAzkMoO7U2WRiz1qjx
A32: 210000066519-0000 | B32: CGE010549 | C32: DESKTOP | D32: 1 | E32: NO | F32: MARCIA VARAS VENEGAS | G32: EJECUTIVOMVV | H32: AIOMP2GDJ1J | I32: AIOMP2GDJ1J | J32: LENOVO | K32: LENOVO TINKCENTRE | L32: 2 NORTE 798 | M32: 1 | N32: TALCA | O32: MAULE | P32: TALCA | Q32: ATENCIÓN COMERCIAL | R32: N/A | S32: Funciona correctamente, sin daños | T32: INTERNO | W32: https://drive.google.com/open?id=1rDTeUZUgveNzyfig47HU4451lsRYF36L
A33: 510000005808-0000 | B33: NO TIENE | C33: TELEFONO IP | D33: 1 | E33: NO | F33: MARCIA VARAS VENEGAS | G33: N/A | H33: FCH1249938T | I33: N/A | J33: CISCO | K33: IP PHONE CP 7911G | L33: 2 NORTE 798 | M33: 1 | N33: TALCA | O33: MAULE | P33: TALCA | Q33: ATENCIÓN COMERCIAL | R33: N/A | T33: INTERNO | W33: https://drive.google.com/open?id=1uMlpIIaH7OIbYbHYdK82SkkT08eCwrwt
A34: 510000006758-0000 | B34: NO TIENE | C34: TELEFONO IP | D34: 1 | E34: SI | F34: MARCIA VARAS VENEGAS | G34: N/A | H34: FCH1246842E | I34: N/A | J34: CISCO | K34: IP PHONE 7941 | L34: 2 NORTE 798 | M34: 1 | N34: TALCA | O34: MAULE | P34: TALCA | Q34: ATENCIÓN COMERCIAL | R34: N/A | T34: INTERNO | W34: https://drive.google.com/open?id=1VZHGaPgWsu8PbFZOSz8GrBjxxMZ5SU8V
A35: 510000005999-0000 | B35: NO TIENE | C35: MONITOR | D35: 1 | E35: SI | F35: MARÍA FUENTES | G35: N/A | H35: FCH1246909N | I35: N/A | J35: CISCO | K35: IP PHONE 7900 | L35: 2 NORTE 798 | M35: 1 | N35: TALCA | O35: MAULE | P35: TALCA | Q35: ATENCIÓN COMERCIAL | R35: N/A | T35: INTERNO | W35: https://drive.google.com/open?id=1tGcpQEyScIxa65oeqIwmQi4G66BQgUiP
A36: 210000036481-0000 | B36: CGE007344 | C36: MONITOR | D36: 1 | E36: SI | F36: MARIA VERONICA | G36: N/A | H36: CNC145P306 | I36: N/A | J36: HP | K36: COMPAQ LE1711 | L36: 2 NORTE 798 | M36: 1 | N36: TALCA | O36: MAULE | P36: TALCA | Q36: ATENCIÓN COMERCIAL | R36: N/A | T36: INTERNO | W36: https://drive.google.com/open?id=1wvtijdNUgdhLfRqA2-HBIH_bfOIrZ-en
A37: 510000005803-0000 | B37: NO TIENE | C37: TELEFONO IP | D37: 1 | E37: NO | F37: MARIA VERONICA | G37: N/A | H37: FCH12479KZH | I37: N/A | J37: CISCO | K37: IP PHONE 7911 | L37: 2 NORTE 798 | M37: 1 | N37: TALCA | O37: MAULE | P37: TALCA | Q37: ATENCIÓN COMERCIAL | R37: N/A | T37: INTERNO | W37: https://drive.google.com/open?id=1BHhq-6BU7lHrRTpvTm9-beVx5_-JLtlC
A38: 210000027319-0000 | B38: NO POSEE | C38: MONITOR | D38: 1 | E38: SI | F38: PABLO FUENZALIDA | G38: PAFUENZALIDAP | H38: CNC115T2F7 | I38: NO APLICA | J38: HP | K38: LE1711 | L38: 2 NORTE 798 | M38: 2 | N38: TALCA | O38: MAULE | P38: TALCA | Q38: ATENCIÓN COMERCIAL | R38: N/A | S38: Funciona correctamente, sin daños | T38: INTERNO | W38: https://drive.google.com/open?id=1_j_Rf1BdRQfftgnNTf04vBZ9cZjDBbZf
A39: 210000027462-0000 | B39: CGE073343 | C39: MONITOR | D39: 1 | E39: SI | F39: PAULA VERENNA VALDIVIA MUÑOZ | G39: N/A | H39: CNC118QSHZ | I39: N/A | J39: HP | K39: COMPAQ LE1711 | L39: 2 NORTE 798 | M39: 1 | N39: TALCA | O39: MAULE | P39: TALCA | Q39: ATENCIÓN COMERCIAL | R39: N/A | T39: INTERNO | W39: https://drive.google.com/open?id=1Rs3Xj9MXMLTdcsZt4OmqBz6uGaLG1Dgk
A40: 210000024836-0000 | B40: CGE002651 | C40: MONITOR | D40: 1 | E40: SI | F40: RODRIGO ANDRES ASTUDILLO GONZALEZ | G40: RAASTUDILLOG | H40: CNC114QD9P | I40: NO APLICA | J40: HP | K40: LE1711 | L40: 2 NORTE 798 | M40: 2 | N40: TALCA | O40: MAULE | P40: TALCA | Q40: ATENCIÓN COMERCIAL | R40: N/A | S40: Funciona correctamente, sin daños | T40: INTERNO | W40: https://drive.google.com/open?id=1YvVWMHGi0F2TRAQ-Uq4BT09-wYNBZ76_
...

Sheet PILOTO
A1: Activo Fijo | B1: Rotulo Entel | C1: estado | D1: Tipo Dispositivo | E1: Unidades | F1: Teléfono | G1: Nombre de Usuario | H1: Usuario de RED | I1: Número de Serie | J1: Hostname | K1: Marca | L1: Modelo | M1: Dirección | N1: Piso | O1: Comuna | P1: Región | Q1: Ciudad | R1: Area | S1: Necesita Alzador | T1: Nombre de usuario Responsable | U1: Tipo Usuario | V1: Observaciones | W1: Observaciones 2
A2: 210000065975-0000 | B2: CG009091 | C2: =VLOOKUP(B2,CONSOLIDADO!$B$1:$B$722,2,FALSE) -> #N/A | D2: DESKTOP | E2: 1 | F2: SI | G2: RODRIGO GERMAN CORTES MARIN | H2: RGCORTESM | I2: 8CN3500B4W | J2: AIO8CN3500B4W | K2: HP | L2: PRO ONE 440 G9 | M2: PEDRO AGUIRRE CERDA 5558 | N2: 2 | O2: ANTOFAGASTA | P2: ANTOFAGASTA | Q2: ANTOFAGASTA | R2: DESPACHO DE OPERACIÓN | S2: SI | T2: RODRIGO GERMAN CORTES MARIN | U2: INTERNO
A3: 2100000029932-0000 | B3: CGE0000365 | C3: =VLOOKUP(B3,CONSOLIDADO!$B$1:$B$722,2,FALSE) -> #N/A | D3: NOTEBOOK | E3: 1 | F3: SI | G3: MARIA DE LOS ANGELES CONTRERAS MARQUEZ | H3: APOYOMACM | I3: PF221WQ0 | J3: NBPF221WQ0-02 | K3: LENOVO | L3: L490 G8 | M3: PEDRO AGUIRRE CERDA 5558 | N3: 2 | O3: ANTOFAGASTA | P3: ANTOFAGASTA | Q3: ANTOFAGASTA | R3: PROGRAMACIÓN | T3: MARIA DE LOS ANGELES CONTRERAS MARQUEZ | U3: INTERNO
A4: 210000062166-0000 | B4: CGE000096 | C4: =VLOOKUP(B4,CONSOLIDADO!$B$1:$B$722,2,FALSE) -> #N/A | D4: DESKTOP | E4: 1 | F4: SI | G4: OSCAR SEGOVIA COLLADO | I4: 4CE237DHB9 | J4: DT4CE237DHB9 | K4: HP | L4: PRO 400 G9 | M4: PEDRO AGUIRRE CERDA 5558 | N4: 2 | O4: ANTOFAGASTA | P4: ANTOFAGASTA | Q4: ANTOFAGASTA | R4: CGE TRANSMISIÓN | T4: OSCAR SEGOVIA COLLADO | U4: INTERNO
A5: 210000062551-0000 | B5: CGE000340 | C5: =VLOOKUP(B5,CONSOLIDADO!$B$1:$B$722,2,FALSE) -> #N/A | D5: NOTEBOOK | E5: 1 | F5: SI | G5: PATRICIO ALEJANDRO VELASQUEZ PARRA | H5: PAVELASQUEZP | I5: 6C5X6LT | J5: NB-5CD236FFXQ | K5: HP | L5: PROBOOK 440 G9 | M5: PEDRO AGUIRRE CERDA 5558 | N5: 2 | O5: ANTOFAGASTA | P5: ANTOFAGASTA | Q5: ANTOFAGASTA | R5: CGE TRANSMISIÓN | S5: NO | T5: PATRICIO ALEJANDRO VELASQUEZ PARRA | U5: INTERNO
A6: 21000025508-0000 | B6: CGE000341 | C6: =VLOOKUP(B6,CONSOLIDADO!$B$1:$B$722,2,FALSE) -> #N/A | D6: MONITOR | E6: 1 | F6: SI | G6: SOPORTENI | H6: N/A | I6: CNC115PRWQ | J6: N/A | K6: HP | L6: LE1711 | M6: PEDRO AGUIRRE CERDA 5558 | N6: 1 | O6: ANTOFAGASTA | P6: ANTOFAGASTA | Q6: ANTOFAGASTA | R6: DELEGACIÓN | T6: SOPORTENI | W6: SOPORTENI
A7: NO TIENE | B7: CGE000344 | C7: =VLOOKUP(B7,CONSOLIDADO!$B$1:$B$722,2,FALSE) -> #N/A | D7: MONITOR | E7: 1 | F7: SI | G7: MILKO HENRY SANCHEZ SALFATE | I7: CN0G8TVHQDC0005H791BA09 | K7: DELL | L7: P2419H | M7: PEDRO AGUIRRE CERDA 5558 | N7: 2 | O7: ANTOFAGASTA | P7: ANTOFAGASTA | Q7: ANTOFAGASTA | R7: DESPACHO DE OPERACIÓN | T7: MILKO HENRY SANCHEZ SALFATE | U7: INTERNO | W7: REVISAR POR CARINA GALLARDO
A8: 210000061086-0000 | B8: CGE000345 | C8: =VLOOKUP(B8,CONSOLIDADO!$B$1:$B$722,2,FALSE) -> #N/A | D8: NOTEBOOK | E8: 1 | F8: SI | G8: YURI LIZETH VALENCIA MURILLO | H8: PROGRAMADORYLVM | I8: 5CD207HF5Z | J8: NB5CD207HF5Z | K8: HP | L8: PROOBOOK 440 G8 | M8: PEDRO AGUIRRE CERDA 5558 | N8: 2 | O8: ANTOFAGASTA | P8: ANTOFAGASTA | Q8: ANTOFAGASTA | R8: PROGRAMACIÓN | T8: YURI LIZETH VALENCIA MURILLO | U8: INTERNO
A9: 210000028482-0000 | B9: CGE000346 | C9: =VLOOKUP(B9,CONSOLIDADO!$B$1:$B$722,2,FALSE) -> #N/A | D9: MONITOR | E9: 1 | F9: SI | G9: PRISCILA VILLARROEL VERGARA | H9: N/A | I9: CNC117018Z | J9: DTMXL6382D4V | K9: HP | L9: LE1711 | M9: PEDRO AGUIRRE CERDA 5558 | N9: 1 | O9: ANTOFAGASTA | P9: ANTOFAGASTA | Q9: ANTOFAGASTA | R9: COMERCIAL | T9: PRISCILA VILLARROEL VERGARA | U9: INTERNO | W9: PISO 1
A10: NO TIENE | B10: CGE000348 | C10: =VLOOKUP(B10,CONSOLIDADO!$B$1:$B$722,2,FALSE) -> #N/A | D10: MONITOR | E10: 1 | F10: SI | G10: PABLO IGNACIO TRIGO ARAYA | I10: CNOKHONGQDC008240NLA05 | K10: DELL | L10: P2417H | M10: PEDRO AGUIRRE CERDA 5558 | N10: 2 | O10: ANTOFAGASTA | P10: ANTOFAGASTA | Q10: ANTOFAGASTA | R10: DESPACHO DE OPERACIÓN | T10: PABLO IGNACIO TRIGO ARAYA | U10: INTERNO
A11: 6981 | B11: CGE000349 | C11: =VLOOKUP(B11,CONSOLIDADO!$B$1:$B$722,2,FALSE) -> #N/A | D11: DESKTOP | E11: 1 | F11: SI | G11: PRISCILA VILLARROEL VERGARA | H11: PVILLARROELV | I11: MXL6382D4V | J11: DTMXL6382D4V | K11: HP | L11: 400 G3 | M11: PEDRO AGUIRRE CERDA 5558 | N11: 1 | O11: ANTOFAGASTA | P11: ANTOFAGASTA | Q11: ANTOFAGASTA | R11: COMERCIAL | T11: PRISCILA VILLARROEL VERGARA | U11: INTERNO | W11: PISO 1
A12: NO TIENE | B12: CGE000351 | C12: =VLOOKUP(B12,CONSOLIDADO!$B$1:$B$722,2,FALSE) -> #N/A | D12: MONITOR | E12: 1 | F12: SI | G12: RODRIGO GERMAN CORTES MARIN | I12: CN0R9F1P742615CG52WS | K12: DELL | L12: U2414HB | M12: PEDRO AGUIRRE CERDA 5558 | N12: 2 | O12: ANTOFAGASTA | P12: ANTOFAGASTA | Q12: ANTOFAGASTA | R12: DESPACHO DE OPERACIÓN | T12: RODRIGO GERMAN CORTES MARIN | U12: INTERNO | W12: REVISAR POR CARINA GALLARDO
A13: 7004 | B13: CGE000357 | C13: =VLOOKUP(B13,CONSOLIDADO!$B$1:$B$722,2,FALSE) -> #N/A | D13: MONITOR | E13: 1 | F13: SI | G13: YURI LIZETH VALENCIA MURILLO | I13: CNORNMH674445OCFCRLS | K13: DELL | L13: P190ST | M13: PEDRO AGUIRRE CERDA 5558 | N13: 2 | O13: ANTOFAGASTA | P13: ANTOFAGASTA | Q13: ANTOFAGASTA | R13: PROGRAMACIÓN | T13: YURI LIZETH VALENCIA MURILLO | U13: INTERNO
A14: NO TIENE | B14: CGE000358 | C14: =VLOOKUP(B14,CONSOLIDADO!$B$1:$B$722,2,FALSE) -> #N/A | D14: MONITOR | E14: 1 | F14: SI | G14: YURI LIZETH VALENCIA MURILLO | I14: CN0RNMH6744450CFCJVS | K14: DELL | L14: P190ST | M14: PEDRO AGUIRRE CERDA 5558 | N14: 2 | O14: ANTOFAGASTA | P14: ANTOFAGASTA | Q14: ANTOFAGASTA | R14: PROGRAMACIÓN | T14: YURI LIZETH VALENCIA MURILLO | U14: INTERNO | W14: REVISAR POR CARINA GALLARDO
A15: 210000060031-0000 | B15: CGE000359 | C15: =VLOOKUP(B15,CONSOLIDADO!$B$1:$B$722,2,FALSE) -> #N/A | D15: NOTEBOOK | E15: 1 | F15: SI | G15: OSCAR MAURICIO VIDELA INOSTROZA | H15: OMVIDELAI | I15: MJ0EJZ0V | J15: NDMJ0EJZ0V | K15: LENOVO | L15: M70S | M15: PEDRO AGUIRRE CERDA 5558 | N15: 2 | O15: ANTOFAGASTA | P15: ANTOFAGASTA | Q15: ANTOFAGASTA | R15: DESPACHO DE OPERACIÓN | T15: OSCAR MAURICIO VIDELA INOSTROZA | U15: INTERNO
A16: 210000026729-0000 | B16: CGE000362 | C16: =VLOOKUP(B16,CONSOLIDADO!$B$1:$B$722,2,FALSE) -> #N/A | D16: MONITOR | E16: 1 | F16: SI | G16: CRISTIAN SAN MARTIN VILLAROEL | I16: CNC115PR29 | K16: HP | L16: COMPAQ LE1711 | M16: PEDRO AGUIRRE CERDA 5558 | N16: 2 | O16: ANTOFAGASTA | P16: ANTOFAGASTA | Q16: ANTOFAGASTA | R16: PROGRAMACIÓN | T16: CRISTIAN SAN MARTIN VILLAROEL | U16: INTERNO
A17: 210000028707-0000 | B17: CGE000363 | C17: =VLOOKUP(B17,CONSOLIDADO!$B$1:$B$722,2,FALSE) -> #N/A | D17: MONITOR | E17: 1 | F17: SI | G17: OSCAR MAURICIO VIDELA INOSTROZA | I17: CNC112QDZN | K17: HP | L17: LE1711 | M17: PEDRO AGUIRRE CERDA 5558 | N17: 2 | O17: ANTOFAGASTA | P17: ANTOFAGASTA | Q17: ANTOFAGASTA | R17: DESPACHO DE OPERACIÓN | T17: OSCAR MAURICIO VIDELA INOSTROZA | U17: INTERNO
A18: 210000016890-0000 | B18: CGE000368 | C18: =VLOOKUP(B18,CONSOLIDADO!$B$1:$B$722,2,FALSE) -> #N/A | D18: MONITOR | E18: 1 | F18: SI | G18: EZEQUIEL MURA MONSALVEZ | H18: APOYOEEMM | I18: CN0N445N7426101N28GU | K18: DELL | L18: E170SB | M18: PEDRO AGUIRRE CERDA 5558 | N18: 2 | O18: ANTOFAGASTA | P18: ANTOFAGASTA | Q18: ANTOFAGASTA | R18: PROGRAMACIÓN | T18: EZEQUIEL MURA MONSALVEZ | U18: INTERNO
A19: NO TIENE | B19: CGE000370 | C19: =VLOOKUP(B19,CONSOLIDADO!$B$1:$B$722,2,FALSE) -> #N/A | D19: DESKTOP | E19: 1 | F19: SI | G19: EZEQUIEL MURA MONSALVEZ | H19: APOYOEEMM | I19: MJ0EJZ29 | J19: NDMJ0EJZ29 | K19: LENOVO | L19: M70S | M19: PEDRO AGUIRRE CERDA 5558 | N19: 2 | O19: ANTOFAGASTA | P19: ANTOFAGASTA | Q19: ANTOFAGASTA | R19: PROGRAMACIÓN | T19: EZEQUIEL MURA MONSALVEZ | U19: INTERNO | W19: REVISAR POR CARINA GALLARDO
A20: 2100000026759-0000 | B20: CGE000373 | C20: =VLOOKUP(B20,CONSOLIDADO!$B$1:$B$722,2,FALSE) -> #N/A | D20: MONITOR | E20: 1 | F20: SI | G20: LUIS ALBERTO TAPIA CASTILLO | I20: CNC118QQQFQ | K20: HP | L20: LE1711 | M20: PEDRO AGUIRRE CERDA 5558 | N20: 1 | O20: ANTOFAGASTA | P20: ANTOFAGASTA | Q20: ANTOFAGASTA | R20: CORDINACION DE PROVEEDORES | T20: LUIS ALBERTO TAPIA CASTILLO | U20: INTERNO | W20: PISO 2
A21: 2100000-27377-0000 | B21: CGE000379 | C21: =VLOOKUP(B21,CONSOLIDADO!$B$1:$B$722,2,FALSE) -> #N/A | D21: MONITOR | E21: 1 | F21: NO | G21: DAYANA RAQUEL FUENTES CASTILLO | I21: CNC118QSB7 | K21: HP | L21: LE1711 | M21: LATORRE 2442 | N21: 1 | O21: ANTOFAGASTA | P21: ANTOFAGASTA | Q21: ANTOFAGASTA | R21: ATENCION CLIENTES | T21: DAYANA RAQUEL FUENTES CASTILLO | U21: EXTERNO
A22: 210000052334-0000 | B22: CGE000382 | C22: =VLOOKUP(B22,CONSOLIDADO!$B$1:$B$722,2,FALSE) -> #N/A | D22: DESKTOP | E22: 1 | F22: SI | G22: MARIA DINORA HUERTA DIAZ | J22: DT4CE7392J0P | K22: HP | L22: 280 G2 | M22: LATORRE 2442 | N22: 1 | O22: ANTOFAGASTA | P22: ANTOFAGASTA | Q22: ANTOFAGASTA | R22: ATENCION CLIENTES | T22: MARIA DINORA HUERTA DIAZ | U22: EXTERNO
A23: 210000061184-0000 | B23: CGE000383 | C23: =VLOOKUP(B23,CONSOLIDADO!$B$1:$B$722,2,FALSE) -> #N/A | D23: NOTEBOOK | E23: 1 | F23: NO | G23: YANALET XIMENA MORALES HIDALGO | H23: EJECUTIVOAT_YMH | I23: 5CD207HF5K | J23: NB5CD207HF5K-1 | K23: HP | L23: PROBOOK 440 G8 | M23: LATORRE 2442 | N23: 1 | O23: ANTOFAGASTA | P23: ANTOFAGASTA | Q23: ANTOFAGASTA | R23: ATENCION CLIENTES | S23: SI | T23: YANALET XIMENA MORALES HIDALGO | U23: EXTERNO
A24: 210000016466-0000 | B24: CGE000385 | C24: =VLOOKUP(B24,CONSOLIDADO!$B$1:$B$722,2,FALSE) -> #N/A | D24: MONITOR | E24: 1 | G24: JOHANA DEL CARMEN PIZARRO ACUÑA | I24: CNDX706H728729BL2JNL | K24: DELL | L24: E1709WF | M24: LATORRE 2442 | N24: 1 | O24: ANTOFAGASTA | P24: ANTOFAGASTA | Q24: ANTOFAGASTA | R24: ATENCION CLIENTES | T24: JOHANA DEL CARMEN PIZARRO ACUÑA | U24: EXTERNO
A25: 210000035124 | B25: CGE000387 | C25: =VLOOKUP(B25,CONSOLIDADO!$B$1:$B$722,2,FALSE) -> #N/A | D25: DESKTOP | E25: 1 | F25: SI | G25: MONICA PATRICIA KALASIC OLAVE | I25: MXL136182F | J25: NO VISIBLE | K25: HP | L25: COMPAQ 8200 | M25: PEDRO AGUIRRE CERDA 5558 | N25: 1 | O25: ANTOFAGASTA | P25: ANTOFAGASTA | Q25: ANTOFAGASTA | R25: SECRETARIA | T25: N/A | U25: INTERNO | W25: EQUIPO SIN USO NO TIENE MONITOR PISO 1
A26: 2100000016212-0000 | B26: CGE000390 | C26: =VLOOKUP(B26,CONSOLIDADO!$B$1:$B$722,2,FALSE) -> #N/A | D26: MONITOR | E26: 1 | F26: SI | G26: JUAN IGANCIO PINTO BARRAZA | I26: CN0N300H641809CB196L | J26: N/A | K26: DELL | L26: E1709WC | M26: PEDRO AGUIRRE CERDA 5558 | N26: 1 | O26: ANTOFAGASTA | P26: ANTOFAGASTA | Q26: ANTOFAGASTA | R26: DELEGACIÓN | T26: JUAN IGANCIO PINTO BARRAZA | U26: INTERNO | W26: PISO 1
A27: 210000015057-0000 | B27: CGE000392 | C27: =VLOOKUP(B27,CONSOLIDADO!$B$1:$B$722,2,FALSE) -> #N/A | D27: DESKTOP | E27: 1 | F27: SI | G27: RODRIGO LORCA PEREZ | I27: J9K2FA01 | K27: DELL | L27: OPTIPLEX 380 | M27: PEDRO AGUIRRE CERDA 5558 | N27: 1 | O27: ANTOFAGASTA | P27: ANTOFAGASTA | Q27: ANTOFAGASTA | R27: DELEGACIÓN | T27: RODRIGO LORCA PEREZ | U27: INTERNO | W27: PC SIN USO Y SIN MONITOR PISO 1
A28: 210000063000-0000 | B28: CGE000394 | C28: =VLOOKUP(B28,CONSOLIDADO!$B$1:$B$722,2,FALSE) -> #N/A | D28: NOTEBOOK | E28: 1 | F28: SI | G28: RODRIGO LORCA PEREZ | I28: HSNQ32C4 | J28: NB5CD30855HF-1 | K28: HP | L28: HQ TRE 71025 | M28: PEDRO AGUIRRE CERDA 5558 | N28: 1 | O28: ANTOFAGASTA | P28: ANTOFAGASTA | Q28: ANTOFAGASTA | R28: DELEGACIÓN | T28: RODRIGO LORCA PEREZ | U28: INTERNO | W28: PISO 1
A29: 210000016259-0000 | B29: CGE000395 | C29: =VLOOKUP(B29,CONSOLIDADO!$B$1:$B$722,2,FALSE) -> #N/A | D29: MONITOR | E29: 1 | F29: SI | G29: JAVIER IGNACIO SANTIAGO ESPOZ | H29: N/A | I29: CN0N300H641809C81B9L | K29: DELL | L29: E1709WC | M29: PEDRO AGUIRRE CERDA 5558 | N29: 1 | O29: ANTOFAGASTA | P29: ANTOFAGASTA | Q29: ANTOFAGASTA | R29: DELEGACIÓN | T29: JAVIER IGNACIO SANTIAGO ESPOZ | U29: INTERNO | W29: SE ENCUENTRA EN TERRENO PISO 1
A30: 210000038636-0000 | B30: CGE000396 | C30: =VLOOKUP(B30,CONSOLIDADO!$B$1:$B$722,2,FALSE) -> #N/A | D30: DOCKING | E30: 1 | F30: SI | G30: RODRIGO LORCA PEREZ | H30: RHLORCAP | I30: 5CG522ZTLC | J30: N/A | K30: HP | L30: 2013 | M30: PEDRO AGUIRRE CERDA 5558 | N30: 1 | O30: ANTOFAGASTA | P30: ANTOFAGASTA | Q30: ANTOFAGASTA | R30: DELEGACIÓN | T30: RODRIGO LORCA PEREZ | U30: INTERNO | W30: PISO 1
A31: 210000045159-0000 | B31: CGE000397 | C31: =VLOOKUP(B31,CONSOLIDADO!$B$1:$B$722,2,FALSE) -> #N/A | D31: NOTEBOOK | E31: 1 | F31: SI | G31: RODRIGO LORCA PEREZ | I31: 5CG6314737 | J31: NO VISIBLE | K31: HP | L31: 840 G3 | M31: PEDRO AGUIRRE CERDA 5558 | N31: 1 | O31: ANTOFAGASTA | P31: ANTOFAGASTA | Q31: ANTOFAGASTA | R31: DELEGACIÓN | T31: RODRIGO LORCA PEREZ | U31: INTERNO | W31: PISO 1
A32: 210000028593-0000 | B32: CGE000398 | C32: =VLOOKUP(B32,CONSOLIDADO!$B$1:$B$722,2,FALSE) -> #N/A | D32: MONITOR | E32: 1 | F32: SI | G32: DANIEL PEREZ MARRE | H32: N/A | I32: CNC117Q05X | J32: N/A | K32: HP | L32: LE1711 | M32: PEDRO AGUIRRE CERDA 5558 | N32: 1 | O32: ANTOFAGASTA | P32: ANTOFAGASTA | Q32: ANTOFAGASTA | R32: PROYECTOS ESPECIALES | T32: DANIEL PEREZ MARRE | U32: INTERNO | W32: PISO 1
A33: 210000050370-0000 | B33: CGE000399 | C33: =VLOOKUP(B33,CONSOLIDADO!$B$1:$B$722,2,FALSE) -> #N/A | D33: DOCKING | E33: 1 | F33: SI | G33: DANIEL PEREZ MARRE | H33: N/A | I33: 5CC747XJXP | J33: N/A | K33: HP | L33: HP 2013 | M33: PEDRO AGUIRRE CERDA 5558 | N33: 1 | O33: ANTOFAGASTA | P33: ANTOFAGASTA | Q33: ANTOFAGASTA | R33: PROYECTOS ESPECIALES | T33: DANIEL PEREZ MARRE | U33: INTERNO | W33: PISO 1
A34: 210000045739-0000 | B34: CGE000400 | C34: =VLOOKUP(B34,CONSOLIDADO!$B$1:$B$722,2,FALSE) -> #N/A | D34: NOTEBOOK | E34: 1 | F34: SI | G34: DANIEL PEREZ MARRE | H34: DAPEREZM | I34: 5CG6411YYX | K34: HP | L34: 840 G3 | M34: PEDRO AGUIRRE CERDA 5558 | N34: 1 | O34: ANTOFAGASTA | P34: ANTOFAGASTA | Q34: ANTOFAGASTA | R34: PROYECTOS ESPECIALES | S34: SI | T34: DANIEL PEREZ MARRE | U34: INTERNO | W34: PISO 1
A35: 2100000026737-0000 | B35: CGE000406 | C35: =VLOOKUP(B35,CONSOLIDADO!$B$1:$B$722,2,FALSE) -> #N/A | D35: MONITOR | E35: 1 | F35: SI | G35: SOPORTENI | I35: CNC118QQD5 | K35: HP | L35: LE1711 | M35: PEDRO AGUIRRE CERDA 5558 | N35: 2 | O35: ANTOFAGASTA | P35: ANTOFAGASTA | Q35: ANTOFAGASTA | R35: CIERRE DE PROYECTO | T35: SOPORTENI
A36: 210000026340-0000 | B36: CGE000409 | C36: =VLOOKUP(B36,CONSOLIDADO!$B$1:$B$722,2,FALSE) -> #N/A | D36: DESKTOP | E36: 1 | F36: SI | G36: CARLOS GOMEZ GOMEZ | H36: ESTAFETANT | I36: MXL1341P8G | K36: HP | L36: COMPAQ 8200 | M36: PEDRO AGUIRRE CERDA 5558 | N36: 1 | O36: ANTOFAGASTA | P36: ANTOFAGASTA | Q36: ANTOFAGASTA | R36: UNIDAD DE SERVICIOS | T36: CARLOS GOMEZ GOMEZ | U36: INTERNO | W36: PISO 1
A37: 210000029866-0000 | B37: CGE000410 | C37: =VLOOKUP(B37,CONSOLIDADO!$B$1:$B$722,2,FALSE) -> #N/A | D37: MONITOR | E37: 1 | F37: SI | G37: JUAN MAXIMO CHIDA OVIEDO | I37: 3CQ132B98P | K37: HP | L37: LE1711 | M37: PEDRO AGUIRRE CERDA 5558 | N37: 2 | O37: ANTOFAGASTA | P37: ANTOFAGASTA | Q37: ANTOFAGASTA | R37: CGE TRANSMISIÓN | T37: JUAN MAXIMO CHIDA OVIEDO | U37: INTERNO
A38: 210000036584-0000 | B38: CGE000411 | C38: =VLOOKUP(B38,CONSOLIDADO!$B$1:$B$722,2,FALSE) -> #N/A | D38: DESKTOP | E38: 1 | F38: SI | G38: SANDRA JAQUELINE MIRANDA GUERRA | H38: SJMIRANDAG | I38: MXL3613NT | K38: HP | L38: COMPAQ 8200 ELITE SMALL | M38: PEDRO AGUIRRE CERDA 5558 | N38: 2 | O38: ANTOFAGASTA | P38: ANTOFAGASTA | Q38: ANTOFAGASTA | R38: SECRETARIA | T38: SANDRA JAQUELINE MIRANDA GUERRA | U38: INTERNO | W38: EQUIPO SIN USO PUESTO COMO SOPORTE DE NOTEBOOK
A39: 210000016747-0000 | B39: CGE000412 | C39: =VLOOKUP(B39,CONSOLIDADO!$B$1:$B$722,2,FALSE) -> #N/A | D39: MONITOR | E39: 1 | F39: SI | G39: JORGE RODRÍGUEZ MARTINEZ | H39: JERODRIGUEZM | I39: CN0N300641809BF1WEL | J39: N/A | K39: DELL | L39: E1709WG | M39: PEDRO AGUIRRE CERDA 5558 | N39: 1 | O39: ANTOFAGASTA | P39: ANTOFAGASTA | Q39: ANTOFAGASTA | R39: OFICINA DE PERSONAL | T39: JORGE RODRÍGUEZ MARTÍNEZ | U39: INTERNO | W39: PISO 1
A40: 210000029906-0000 | B40: CGE000413 | C40: =VLOOKUP(B40,CONSOLIDADO!$B$1:$B$722,2,FALSE) -> #N/A | D40: MONITOR | E40: 1 | F40: SI | G40: KATHLIN PEREZ FLORES | H40: KMPEREZF | I40: CNC117Q17V | J40: N/A | K40: HP | L40: LE1711 | M40: PEDRO AGUIRRE CERDA 5558 | N40: 1 | O40: ANTOFAGASTA | P40: ANTOFAGASTA | Q40: ANTOFAGASTA | R40: ADMINISTRATIVA | T40: KATHLIN PEREZ FLORES | U40: INTERNO | W40: PISO 1
...

Sheet DUPLICADAS REVISAR
A1: Activo Fijo | B1: Rotulo Entel | C1: Tipo Dispositivo | D1: Unidades | E1: Teléfono | F1: Nombre de Usuario | G1: Usuario de RED | H1: Número de Serie | I1: Hostname | J1: Marca | K1: Modelo | L1: Dirección | M1: Piso | N1: Comuna | O1: Región | P1: Ciudad | Q1: Area | R1: Necesita Alzador | S1: Nombre de usuario Responsable | T1: Tipo Usuario | U1: Observaciones | V1: Observaciones 2
A2: 210000062193-0000 | B2: CGE000033 | C2: MONITOR | D2: 1 | E2: NO | H2: BZRYH4ZT400334E | I2: NO | J2: SAMSUNG | K2: LC24F390FHLXZS | L2: PRESIDENTE RIESCO 5561 | M2: 14 | N2: LAS CONDES | O2: METROPOLITANA | P2: SANTIAGO | Q2: TRANSFORMACION DIGITAL | R2: NO | T2: INTERNO
A3: 210000026729-0000 | B3: CGE000362 | C3: MONITOR | D3: 1 | E3: SI | F3: CELSO GABRIEL SAAVEDRA PALMA | H3: CNC115PR29 | J3: HP | K3: LE1711 | L3: PEDRO AGUIRRE CERDA 5558 | M3: 1 | N3: ANTOFAGASTA | O3: ANTOFAGASTA | P3: ANTOFAGASTA | Q3: GERENCIA | S3: CELSO GABRIEL SAAVEDRA PALMA | T3: INTERNO
A4: 210000061116-0000 | B4: CGE001186 | C4: NOTEBOOK | E4: SI | F4: Magali Cordoba Hinojosa | G4: mmcordovah | H4: 5CD107HD3Z | I4: NB5CD107HD3Z | J4: HP | K4: PROBOOK 440 G8 | L4: Av Presidente riesco 5561 | M4: 12 | N4: Las Condes | O4: Metropolitana | P4: Santiago | Q4: Tesoreria | R4: SI | S4: Karin Valenzuela | T4: INTERNO
A5: 210000029723-0000 | B5: CGE001198 | C5: MONITOR | D5: 1 | E5: SI | F5: PEDRO CORDOVA GALVEZ | G5: PCORDOVAG | H5: 61BCMAR6WWW9057375 | I5: NO | J5: LENOVO | K5: D17238FT0 | L5: PRESIDENTE RIESCO 5561 | M5: 15 | N5: LAS CONDES | O5: METROPOLITANA | P5: SANTIAGO | Q5: PLANIFICACION Y CONSTRUCCION DE LA RED | R5: NO | S5: FERNANDO SANHUEZA | T5: INTERNO
A6: 210000062536-0000 | B6: CGE001237 | C6: NOTEBOOK | D6: 1 | E6: SI | F6: IVAN SEPULVEDA VASQUEZ | G6: ISEPULVEDAV | H6: 5CD236FG8Q | I6: NB5CD236FG8Q | J6: HP | K6: PROBOOK 440 G9 | L6: PRESIDENTE RIESCO 5561 | M6: 15 | N6: LAS CONDES | O6: METROPOLITANA | P6: SANTIAGO | Q6: CONSTRUCCION TX | R6: NO | S6: NELSON ANTILLANCA | T6: INTERNO
A7: 210000062403-0000 | B7: CGE001238 | C7: MONITOR | D7: 1 | E7: SI | F7: IVAN SEPULVEDA VASQUEZ | G7: ISEPULVEDAV | H7: 212NTVS10975 | I7: NO | J7: LG | K7: 24MK430H | L7: PRESIDENTE RIESCO 5561 | M7: 15 | N7: LAS CONDES | O7: METROPOLITANA | P7: SANTIAGO | Q7: CONSTRUCCION TX | R7: NO | S7: NELSON ANTILLANCA | T7: INTERNO
A8: 210000028255-0000 | B8: CGE001342 | C8: MONITOR | D8: 1 | E8: SI | F8: KAREN CORTEZ-MONRROY | G8: KCORTEZM | H8: NO LEGIBLE | I8: NO | J8: HP | K8: LE1711 | L8: PRESIDENTE RIESCO 5561 | M8: PISO 16 | N8: LAS CONDES | O8: METROPOLITANA | P8: SANTIAGO | Q8: PERSONAS | R8: NO | S8: MARIA EUGENIA CID | T8: INTERNO | V8: SERIE NO LEGIBLE
A9: 210000062502-0000 | B9: CGE001346 | C9: NOTEBOOK | D9: 1 | E9: SI | F9: PEDRO VARGAS ABURTO | G9: PJVARGASA | H9: CD236FG92 | I9: NB5CD236FG92 | J9: HP | K9: PROBOOK 440 G9 | L9: PRESIDENTE RIESCO 5561 | M9: 15 | N9: LAS CONDES | O9: METROPOLITANA | P9: SANTIAGO | Q9: PLANIFICACION Y CONSTRUCCION DE LA RED | R9: NO | S9: ADAM CASTILLO SALAS | T9: INTERNO
A10: 210000021080-0000 | B10: CGE001403 | C10: MONITOR | F10: Magali Cordoba Hinojosa | G10: mmcordovah | H10: CN0X706H728721W1L | J10: DELL | K10: E1709WC | L10: Av Presidente riesco 5561 | M10: 12 | N10: Las Condes | O10: Metropolitana | P10: Santiago | Q10: Tesoreria | R10: SI | S10: Karin Valenzuela | T10: INTERNO
A11: 210000062371-0000 | B11: CGE001527 | C11: MONITOR | D11: 1 | E11: SI | F11: GIOVANNY MALLEA VERGARA | G11: GAMALLEAV | H11: 212NTBK10973 | I11: NO | J11: LG | K11: 24MK430H | L11: PDTE. RIESCO 5561 | M11: 16 | N11: LAS CONDES | O11: METROPOLITANA | P11: SANTIAGO | Q11: TARIFAS Y CONTABILIDAD REGULATORIA | R11: NO | S11: NICOLÁS GUTIERREZ ZEPEDA | T11: INTERNO
A12: 210000061612-0001 | B12: CGE001533 | C12: NOTEBOOK | D12: 1 | E12: SI | F12: MILTON HUILIPAN MELIN | G12: MHUILIPANM | H12: CD20M073 | I12: NB5CD20M073 | J12: HP | K12: PROBOOK 440 G7 | L12: PRESIDENTE RIESCO 5561 | M12: 14 | N12: LAS CONDES | O12: METROPOLITANA | P12: SANTIAGO | Q12: COBRANZA | R12: NO | S12: RODRIGO ALQUINTA | T12: INTERNO | V12: USARIO SIN MONITOR
A13: 210000060767-0000 | B13: CGE001570 | C13: NOTEBOOK | D13: 1 | E13: NO | F13: GUILLERMO AYANCA GALLARDO | G13: GAYANCANG | H13: CD1463LMQ | I13: NB5CD1463LMQ | J13: HP | K13: PROBOOK 440 G8 | L13: PRESIDENTE RIESCO 5561 | M13: 15 | N13: LAS CONDES | O13: METROPOLITANA | P13: SANTIAGO | Q13: PLANIFICACION Y CONSTRUCCION DE LA RED | R13: NO | S13: CAMILA BRAVO | T13: INTERNO
A14: 210000026458-0000 | B14: CGE001585 | C14: MONITOR | D14: 1 | E14: NO | F14: SOPORTE NI | G14: NO | H14: CNC115T0J8 | I14: NO | J14: HP | K14: LE1711 | L14: PRESIDENTE RIESCO 5561 | M14: 15 | N14: LAS CONDES | O14: METROPOLITANA | P14: SANTIAGO | Q14: PLANIFICACION Y CONSTRUCCION DE LA RED | R14: NO | S14: SOPORTE NI | T14: INTERNO | V14: MONITOR SOLO EN ESCRITORIO SIN USUARIO
A15: 210000062499-0000 | B15: CGE001598 | C15: NOTEBOOK | D15: 1 | E15: SI | F15: CLAUDIO VALDIVIA STEEL | G15: CAVALDIVIAS | H15: CD236FG95 | I15: NB5CD236FG95 | J15: HP | K15: PROBOOK 440 G9 | L15: PRESIDENTE RIESCO 5561 | M15: 15 | N15: LAS CONDES | O15: METROPOLITANA | P15: SANTIAGO | Q15: PLANIFICACION Y CONSTRUCCION DE LA RED | R15: NO | S15: FELIPE GONZALEZ | T15: INTERNO
A16: NO TIENE | B16: CGE001599 | C16: MONITOR | D16: 1 | E16: SI | F16: CLAUDIO VALDIVIA STEEL | G16: CAVALDIVIAS | H16: M3344554 | I16: NO | J16: ASUS | K16: VG289 | L16: PRESIDENTE RIESCO 5561 | M16: 15 | N16: LAS CONDES | O16: METROPOLITANA | P16: SANTIAGO | Q16: PLANIFICACION Y CONSTRUCCION DE LA RED | R16: NO | S16: FELIPE GONZALEZ | T16: INTERNO | V16: REVISAR POR CARINA GALLARDO
A17: 210000060783-0000 | B17: CGE001666 | C17: NOTEBOOK | D17: 1 | E17: SI | F17: RICHARD CESPEDES MORI | G17: RCESPEDES | H17: CD1463LCW | I17: NB5CD1463LCW | J17: HP | K17: PROBOOK 440 G8 | L17: PRESIDENTE RIESCO 5561 | M17: 15 | N17: LAS CONDES | O17: METROPOLITANA | P17: SANTIAGO | Q17: PLANIFICACION Y CONSTRUCCION DE LA RED | R17: SI | S17: JAVIER SANTORO | T17: INTERNO
A18: 210000021748-0000 | B18: CGE001667 | C18: MONITOR | D18: 1 | E18: SI | F18: RICHARD CESPEDES MORI | G18: RCESPEDES | H18: CN014K0N74445084AZCU | I18: NO | J18: DELL | K18: 014KON | L18: PRESIDENTE RIESCO 5561 | M18: 15 | N18: LAS CONDES | O18: METROPOLITANA | P18: SANTIAGO | Q18: PLANIFICACION Y CONSTRUCCION DE LA RED | R18: SI | S18: JAVIER SANTORO | T18: INTERNO
A19: 210000062492-0000 | B19: CGE001969 | C19: NOTEBOOK | D19: 1 | E19: SI | F19: Susana Marquez Gonzalez | G19: semarquezg | H19: 5CD236FFHT | I19: NB5CD236FFHT | J19: HP | K19: PROBOOK 440 G9 | L19: Av Presidente riesco 5561 | M19: 12 | N19: Las Condes | O19: Metropolitana | P19: Santiago | Q19: Tesoreria | R19: SI | S19: Karin Valenzuela | T19: INTERNO
A20: 210000028284-0000 | B20: CGE001970 | C20: MONITOR | F20: Susana Marquez Gonzalez | G20: semarquezg | H20: CNC112QDPF | J20: HP | K20: LE 1711 | L20: Av Presidente riesco 5561 | M20: 12 | N20: Las Condes | O20: Metropolitana | P20: Santiago | Q20: Tesoreria | R20: SI | S20: Karin Valenzuela | T20: INTERNO
A21: 210000051053-0000 | B21: CGE001984 | C21: NOTEBOOK | E21: NO | F21: Enrique Aravena Cifuentes | G21: earavena | H21: 5CG749632X | I21: NB5CG749632X | J21: HP | K21: ELITEBOOK 840 G3 | L21: Av Presidente riesco 5561 | M21: 12 | N21: Las Condes | O21: Metropolitana | P21: Santiago | Q21: Tesoreria | R21: SI | S21: Karin Valenzuela | T21: INTERNO
A22: 210000060266-0000 | B22: CGE001987 | C22: NOTEBOOK | E22: SI | F22: Yessica Perez Ibarra | G22: yperez | H22: R9136WY0 | I22: NBR9136WY0 | J22: Lenovo | K22: L13 YOGA | L22: Av Presidente riesco 5561 | M22: 12 | N22: Las Condes | O22: Metropolitana | P22: Santiago | Q22: Tesoreria | R22: SI | S22: Karin Valenzuela | T22: INTERNO
A23: 210000026794-0000 | B23: CGE002222 | C23: MONITOR | D23: 1 | E23: NO | F23: SOPORTE NI | G23: NO | H23: CNC115T03H | I23: NO | J23: HP | K23: LE1711 | L23: PRESIDENTE RIESCO 5561 | M23: 15 | N23: LAS CONDES | O23: METROPOLITANA | P23: SANTIAGO | Q23: PLANIFICACION Y CONSTRUCCION DE LA RED | R23: NO | S23: SOPORTE NI | T23: INTERNO | V23: MONITOR SOLO EN ESCRITORIO SIN USUARIO
A24: 210000060347-0000 | B24: CGE002643 | C24: NOTEBOOK | D24: 1 | E24: SI | F24: NATHALY JAVIERA OLMOS CARVAJAL | G24: NJOLMOSC | H24: 5CD116Q46R | I24: NB5CD116Q46R | J24: HP | K24: PROBOOK 440 G7 | L24: PRESIDENTE RIESCO 5561 | M24: 15 | N24: LAS CONDES | O24: METROPOLITANA | P24: SANTIAGO | Q24: PLANIFICACION Y CONSTRUCCION DE LA RED | R24: NO | S24: CAMILA BRAVO | T24: INTERNO
A25: 210000060763-0000 | B25: CGE002727 | C25: NOTEBOOK | E25: NO | F25: Karin Valenzuela Fuenzalida | G25: kavalenzuelaf | H25: 5CS1463LF6 | I25: NB5CS1463LF6 | J25: HP | K25: PROBOOK 440 G9 | L25: Av Presidente riesco 5561 | M25: 12 | N25: Las Condes | O25: Metropolitana | P25: Santiago | Q25: Tesoreria | R25: SI | S25: Karin Valenzuela | T25: INTERNO
A26: 210000016488-0000 | B26: CGE002731 | C26: MONITOR | F26: Carolina Guardera Ortega | G26: Cguarderao | H26: CN0N300H64180 | J26: DELL | K26: E1709WC | L26: Av Presidente riesco 5561 | M26: 12 | N26: Las Condes | O26: Metropolitana | P26: Santiago | Q26: Tesoreria | R26: SI | S26: Karin Valenzuela | T26: INTERNO
A27: 210000044960-0000 | B27: CGE002734 | C27: NOTEBOOK | E27: SI | F27: Carolina Guardera Ortega | G27: Cguarderao | H27: 5CG63145YD | I27: NB5CG63145YD | J27: HP | K27: ELITEBOOK 840 G3 | L27: Av Presidente riesco 5561 | M27: 12 | N27: Las Condes | O27: Metropolitana | P27: Santiago | Q27: Tesoreria | R27: SI | S27: Karin Valenzuela | T27: INTERNO
A28: 210000062590-0000 | B28: CGE002736 | C28: NOTEBOOK | D28: 1 | E28: SI | F28: Evelyn Rodriguez Becerra | G28: ebrodriguezb | H28: 5CD236FGDD | I28: NB5CD236FGDD | J28: HP | K28: PROBOOK 440 G9 | L28: Av Presidente riesco 5561 | M28: 12 | N28: Las Condes | O28: Metropolitana | P28: Santiago | Q28: Tesoreria | R28: SI | S28: Karin Valenzuela | T28: INTERNO
A29: 210000045899-0000 | B29: CGE002739 | C29: NOTEBOOK | E29: NO | F29: Valeria Galaz Araya | G29: vcgalaza | H29: 5CG6402H0V | I29: NB5CG6402H0V | J29: HP | K29: ELITEBOOK 840 G3 | L29: Av Presidente riesco 5561 | M29: 12 | N29: Las Condes | O29: Metropolitana | P29: Santiago | Q29: Tesoreria | R29: SI | S29: Karin Valenzuela | T29: INTERNO
A30: 210000060798-0000 | B30: CGE003711 | C30: NOTEBOOK | D30: 1 | E30: SI | F30: DIEGO ANCAVIL CARRASCO | G30: DANCAVILC | H30: W009SEQ | I30: NBW-009SEQ | J30: LENOVO | K30: 20VL-S1FJ04 | L30: PRESIDENTE RIESCO 5561 | M30: 15 | N30: LAS CONDES | O30: METROPOLITANA | P30: SANTIAGO | Q30: PLANIFICACION Y CONSTRUCCION DE LA RED | R30: NO | S30: FELIPE GONZALEZ | T30: INTERNO
A31: NO TIENE | B31: CGE003712 | C31: MONITOR | D31: 1 | E31: SI | F31: DIEGO ANCAVIL CARRASCO | G31: DANCAVILC | H31: CN8X1R3 | I31: NO | J31: DELL | K31: P2422H | L31: PRESIDENTE RIESCO 5561 | M31: 15 | N31: LAS CONDES | O31: METROPOLITANA | P31: SANTIAGO | Q31: PLANIFICACION Y CONSTRUCCION DE LA RED | R31: NO | S31: FELIPE GONZALEZ | T31: INTERNO | V31: REVISAR POR CARINA GALLARDO
A32: 210000062798-0000 | B32: CGE004015 | C32: MONITOR | D32: 1 | E32: SI | F32: SEBASTIAN ECHEVERRIA | G32: SDECHEVERRIA | H32: 4X3ZH4TW205540J | I32: NO | J32: SAMSUNG | K32: S24A336NHL | L32: PRESIDENTE RIESCO 5561 | M32: 15 | N32: LAS CONDES | O32: METROPOLITANA | P32: SANTIAGO | Q32: ECONOMIA, DISEÑO Y TX | R32: NO | S32: NELSON ANTILLANCA | T32: INTERNO
A33: 210000062824-0000 | B33: CGE004041 | C33: MONITOR | F33: Enrique Aravena Cifuentes | G33: earavena | H33: 4X3ZH4TW206135Z | J33: Samsung | K33: S24A33 | L33: Av Presidente riesco 5561 | M33: 12 | N33: Las Condes | O33: Metropolitana | P33: Santiago | Q33: Tesoreria | R33: SI | S33: Karin Valenzuela | T33: INTERNO
A34: NO TIENE | B34: CGE004086 | C34: NOTEBOOK | D34: 1 | E34: SI | F34: SEBASTIAN ECHEVERRIA | G34: SDECHEVERRIA | H34: CD30855G0 | I34: NB5CD30855G0 | J34: HP | K34: PROBOOK 440 G9 | L34: PRESIDENTE RIESCO 5561 | M34: 15 | N34: LAS CONDES | O34: METROPOLITANA | P34: SANTIAGO | Q34: ECONOMIA, DISEÑO Y TX | R34: NO | S34: NELSON ANTILLANCA | T34: INTERNO | V34: REVISAR POR CARINA GALLARDO
A35: 210000062872-0000 | B35: CGE004099 | C35: MONITOR | F35: Yessica Perez Ibarra | G35: yperez | H35: 4X3ZH4TW203938H | J35: Samsung | K35: S24A33 | L35: Av Presidente riesco 5561 | M35: 12 | N35: Las Condes | O35: Metropolitana | P35: Santiago | Q35: Tesoreria | R35: SI | S35: Karin Valenzuela | T35: INTERNO
A36: NO TIENE | B36: CGE005199 | C36: NOTEBOOK | D36: 1 | E36: SI | F36: BEATRIZ GUERRA GACITUA | G36: BGUERRAG | H36: KZ79W3 | I36: NBKZ79W3 | J36: DELL | K36: LATITUDE 5440 | L36: PRESIDENTE RIESCO 5561 | M36: 15 | N36: LAS CONDES | O36: METROPOLITANA | P36: SANTIAGO | Q36: SUPERVICION DE SEGURIDAD | R36: NO | S36: CHRISTIAN OLAVE | T36: INTERNO | V36: REVISAR POR CARINA GALLARDO
A37: 210000063933-0000 | B37: CGE005319 | C37: MONITOR | D37: 1 | E37: NO | F37: GUILLERMO AYANCA GALLARDO | G37: GAYANCANG | H37: 7VHGTZ3 | I37: NO | J37: DELL | K37: P2422M | L37: PRESIDENTE RIESCO 5561 | M37: 15 | N37: LAS CONDES | O37: METROPOLITANA | P37: SANTIAGO | Q37: PLANIFICACION Y CONSTRUCCION DE LA RED | R37: NO | S37: CAMILA BRAVO | T37: INTERNO
A38: NO TIENE | B38: CGE005553 | C38: NOTEBOOK | D38: 1 | E38: SI | F38: YENNY LORETO DIAZ ORELLANA | G38: YLDIAZO | H38: 3BHB9W3 | I38: NB3BHB9W3 | J38: DELL | K38: LATITUDE 5440 13G | L38: PEDRO AGUIRRE CERDA 5558 | M38: 1 | N38: ANTOFAGASTA | O38: ANTOFAGASTA | P38: ANTOFAGASTA
A39: 210000065128-0000 | B39: CGE007923 | C39: NOTEBOOK | D39: 1 | E39: NO | H39: 5CD421CDJM | I39: NB5CD421CDJM | J39: HP | K39: PROBOOK 440 G9 | L39: PRESIDENTE RIESCO 5561 | M39: 14 | N39: LAS CONDES | O39: METROPOLITANA | P39: SANTIAGO | Q39: TRANSFORMACION DIGITAL | R39: NO | T39: INTERNO
A40: NO TIENE | B40: CGE007929 | C40: MONITOR | D40: 1 | E40: SI | F40: FABIOLA DUARTE MORALES | G40: FDUARTEM | H40: 307NDZJK4325 | I40: NO | J40: LG | K40: 23EA53VQ | L40: PRESIDENTE RIESCO 5561 | M40: 15 | N40: LAS CONDES | O40: METROPOLITANA | P40: SANTIAGO | Q40: ASUNTOS ADMINISTRATIVOS | R40: NO | S40: JAVIERA SANCHEZ | T40: INTERNO | V40: REVISAR POR CARINA GALLARDO
...
